<?xml version="1.0"?>
<robot name="HiroNX"
       xmlns:xi="http://www.w3.org/2001/XInclude"
       xmlns:gazebo="http://playerstage.sourceforge.net/gazebo/xmlschema/#gz"
       xmlns:model="http://playerstage.sourceforge.net/gazebo/xmlschema/#model"
       xmlns:sensor="http://playerstage.sourceforge.net/gazebo/xmlschema/#sensor"
       xmlns:body="http://playerstage.sourceforge.net/gazebo/xmlschema/#body"
       xmlns:geom="http://playerstage.sourceforge.net/gazebo/xmlschema/#geom"
       xmlns:joint="http://playerstage.sourceforge.net/gazebo/xmlschema/#joint"
       xmlns:interface="http://playerstage.sourceforge.net/gazebo/xmlschema/#interface"
       xmlns:rendering="http://playerstage.sourceforge.net/gazebo/xmlschema/#rendering"
       xmlns:renderable="http://playerstage.sourceforge.net/gazebo/xmlschema/#renderable"
       xmlns:controller="http://playerstage.sourceforge.net/gazebo/xmlschema/#controller"
       xmlns:physics="http://playerstage.sourceforge.net/gazebo/xmlschema/#physics">
  <link name="WAIST">
    <visual>
      <origin xyz="0 0 0" rpy="0 -0 0"/>
      <geometry>
        <mesh filename="package://hironx_moveit_config/models/meshes/WAIST_mesh.dae" scale="1 1 1" />
      </geometry>
    </visual>
    <collision>
      <origin xyz="0 0 0" rpy="0 -0 0"/>
      <geometry>
        <mesh filename="package://hironx_moveit_config/models/meshes/WAIST_mesh.dae" scale="1 1 1" />
      </geometry>
    </collision>
    <inertial>
      <mass value="0" />
      <origin xyz="0 0 0" rpy="0 -0 0"/>
      <inertia ixx="0" ixy="0" ixz="0" iyy="0" iyz="0" izz="0"/>
    </inertial>
  </link>
  <link name="CHEST_JOINT0_Link">
    <visual>
      <origin xyz="0 0 0" rpy="0 -0 0"/>
      <geometry>
        <mesh filename="package://hironx_moveit_config/models/meshes/CHEST_JOINT0_Link_mesh.dae" scale="1 1 1" />
      </geometry>
    </visual>
    <collision>
      <origin xyz="0 0 0" rpy="0 -0 0"/>
      <geometry>
        <mesh filename="package://hironx_moveit_config/models/meshes/CHEST_JOINT0_Link_mesh.dae" scale="1 1 1" />
      </geometry>
    </collision>
    <inertial>
      <mass value="0" />
      <origin xyz="0 0 0" rpy="0 -0 0"/>
      <inertia ixx="0" ixy="0" ixz="0" iyy="0" iyz="0" izz="0"/>
    </inertial>
  </link>
  <link name="HEAD_JOINT0_Link">
    <visual>
      <origin xyz="0 0 0.5695" rpy="0 -0 0"/>
      <geometry>
        <mesh filename="package://hironx_moveit_config/models/meshes/HEAD_JOINT0_Link_mesh.dae" scale="1 1 1" />
      </geometry>
    </visual>
    <collision>
      <origin xyz="0 0 0.5695" rpy="0 -0 0"/>
      <geometry>
        <mesh filename="package://hironx_moveit_config/models/meshes/HEAD_JOINT0_Link_mesh.dae" scale="1 1 1" />
      </geometry>
    </collision>
    <inertial>
      <mass value="0.317929" />
      <origin xyz="-2.292e-05 0.00547848 -0.00784016" rpy="0 -0 0"/>
      <inertia ixx="0" ixy="0" ixz="0" iyy="0" iyz="0" izz="0"/>
    </inertial>
  </link>
  <link name="HEAD_JOINT1_Link">
    <visual>
      <origin xyz="0 0 0" rpy="0 -0 0"/>
      <geometry>
        <mesh filename="package://hironx_moveit_config/models/meshes/HEAD_JOINT1_Link_mesh.dae" scale="1 1 1" />
      </geometry>
    </visual>
    <collision>
      <origin xyz="0 0 0" rpy="0 -0 0"/>
      <geometry>
        <mesh filename="package://hironx_moveit_config/models/meshes/HEAD_JOINT1_Link_mesh.dae" scale="1 1 1" />
      </geometry>
    </collision>
    <inertial>
      <mass value="0.0808593" />
      <origin xyz="5.02e-06 -0.0166777 0.0163153" rpy="0 -0 0"/>
      <inertia ixx="0" ixy="0" ixz="0" iyy="0" iyz="0" izz="0"/>
    </inertial>
  </link>
  <link name="LARM_JOINT0_Link">
    <visual>
      <origin xyz="0 0.145 0.370296" rpy="-0.261799 0 0"/>
      <geometry>
        <mesh filename="package://hironx_moveit_config/models/meshes/LARM_JOINT0_Link_mesh.dae" scale="1 1 1" />
      </geometry>
    </visual>
    <collision>
      <origin xyz="0 0.145 0.370296" rpy="-0.261799 0 0"/>
      <geometry>
        <mesh filename="package://hironx_moveit_config/models/meshes/LARM_JOINT0_Link_mesh.dae" scale="1 1 1" />
      </geometry>
    </collision>
    <inertial>
      <mass value="1.32626" />
      <origin xyz="-0.00226388 -0.00521383 0.0156081" rpy="0 -0 0"/>
      <inertia ixx="0" ixy="0" ixz="0" iyy="0" iyz="0" izz="0"/>
    </inertial>
  </link>
  <link name="LARM_JOINT1_Link">
    <visual>
      <origin xyz="0 0 0" rpy="0 -0 0"/>
      <geometry>
        <mesh filename="package://hironx_moveit_config/models/meshes/LARM_JOINT1_Link_mesh.dae" scale="1 1 1" />
      </geometry>
    </visual>
    <collision>
      <origin xyz="0 0 0" rpy="0 -0 0"/>
      <geometry>
        <mesh filename="package://hironx_moveit_config/models/meshes/LARM_JOINT1_Link_mesh.dae" scale="1 1 1" />
      </geometry>
    </collision>
    <inertial>
      <mass value="1.14898" />
      <origin xyz="-5.236e-05 0.0583134 -0.107061" rpy="0 -0 0"/>
      <inertia ixx="0" ixy="0" ixz="0" iyy="0" iyz="0" izz="0"/>
    </inertial>
  </link>
  <link name="LARM_JOINT2_Link">
    <visual>
      <origin xyz="0 0.095 -0.25" rpy="0 -0 0"/>
      <geometry>
        <mesh filename="package://hironx_moveit_config/models/meshes/LARM_JOINT2_Link_mesh.dae" scale="1 1 1" />
      </geometry>
    </visual>
    <collision>
      <origin xyz="0 0.095 -0.25" rpy="0 -0 0"/>
      <geometry>
        <mesh filename="package://hironx_moveit_config/models/meshes/LARM_JOINT2_Link_mesh.dae" scale="1 1 1" />
      </geometry>
    </collision>
    <inertial>
      <mass value="0.577518" />
      <origin xyz="-2.254e-05 0.00167107 -0.0715116" rpy="0 -0 0"/>
      <inertia ixx="0" ixy="0" ixz="0" iyy="0" iyz="0" izz="0"/>
    </inertial>
  </link>
  <link name="LARM_JOINT3_Link">
    <visual>
      <origin xyz="-0.03 0 0" rpy="0 -0 0"/>
      <geometry>
        <mesh filename="package://hironx_moveit_config/models/meshes/LARM_JOINT3_Link_mesh.dae" scale="1 1 1" />
      </geometry>
    </visual>
    <collision>
      <origin xyz="-0.03 0 0" rpy="0 -0 0"/>
      <geometry>
        <mesh filename="package://hironx_moveit_config/models/meshes/LARM_JOINT3_Link_mesh.dae" scale="1 1 1" />
      </geometry>
    </collision>
    <inertial>
      <mass value="0.457418" />
      <origin xyz="-1.788e-05 -0.00395812 -0.202731" rpy="0 -0 0"/>
      <inertia ixx="0" ixy="0" ixz="0" iyy="0" iyz="0" izz="0"/>
    </inertial>
  </link>
  <link name="LARM_JOINT4_Link">
    <visual>
      <origin xyz="0 0 -0.235" rpy="0 -0 0"/>
      <geometry>
        <mesh filename="package://hironx_moveit_config/models/meshes/LARM_JOINT4_Link_mesh.dae" scale="1 1 1" />
      </geometry>
    </visual>
    <collision>
      <origin xyz="0 0 -0.235" rpy="0 -0 0"/>
      <geometry>
        <mesh filename="package://hironx_moveit_config/models/meshes/LARM_JOINT4_Link_mesh.dae" scale="1 1 1" />
      </geometry>
    </collision>
    <inertial>
      <mass value="0.418434" />
      <origin xyz="0.00243131 0.00379733 -0.0577036" rpy="0 -0 0"/>
      <inertia ixx="0" ixy="0" ixz="0" iyy="0" iyz="0" izz="0"/>
    </inertial>
  </link>
  <link name="LARM_JOINT5_Link">
    <visual>
      <origin xyz="-0.04 0 -0.09" rpy="0 -0 0"/>
      <geometry>
        <mesh filename="package://hironx_moveit_config/models/meshes/LARM_JOINT5_Link_mesh.dae" scale="1 1 1" />
      </geometry>
    </visual>
    <collision>
      <origin xyz="-0.04 0 -0.09" rpy="0 -0 0"/>
      <geometry>
        <mesh filename="package://hironx_moveit_config/models/meshes/LARM_JOINT5_Link_mesh.dae" scale="1 1 1" />
      </geometry>
    </collision>
    <inertial>
      <mass value="1.05156" />
      <origin xyz="-0.048476 -3.2e-06 -0.0388988" rpy="0 -0 0"/>
      <inertia ixx="0" ixy="0" ixz="0" iyy="0" iyz="0" izz="0"/>
    </inertial>
  </link>
  <link name="LHAND_JOINT0_Link">
    <visual>
      <origin xyz="-0.0299 -0.033 0" rpy="0 -0 0"/>
      <geometry>
        <mesh filename="package://hironx_moveit_config/models/meshes/LHAND_JOINT0_Link_mesh.dae" scale="1 1 1" />
      </geometry>
    </visual>
    <collision>
      <origin xyz="-0.0299 -0.033 0" rpy="0 -0 0"/>
      <geometry>
        <mesh filename="package://hironx_moveit_config/models/meshes/LHAND_JOINT0_Link_mesh.dae" scale="1 1 1" />
      </geometry>
    </collision>
    <inertial>
      <mass value="0.01" />
      <origin xyz="0 0 0" rpy="0 -0 0"/>
      <inertia ixx="0" ixy="0" ixz="0" iyy="0" iyz="0" izz="0"/>
    </inertial>
  </link>
  <link name="LHAND_JOINT1_Link">
    <visual>
      <origin xyz="-0.0419 0 0" rpy="0 -0 0"/>
      <geometry>
        <mesh filename="package://hironx_moveit_config/models/meshes/LHAND_JOINT1_Link_mesh.dae" scale="1 1 1" />
      </geometry>
    </visual>
    <collision>
      <origin xyz="-0.0419 0 0" rpy="0 -0 0"/>
      <geometry>
        <mesh filename="package://hironx_moveit_config/models/meshes/LHAND_JOINT1_Link_mesh.dae" scale="1 1 1" />
      </geometry>
    </collision>
    <inertial>
      <mass value="0.01" />
      <origin xyz="0 0 0" rpy="0 -0 0"/>
      <inertia ixx="0" ixy="0" ixz="0" iyy="0" iyz="0" izz="0"/>
    </inertial>
  </link>
  <link name="LHAND_JOINT2_Link">
    <visual>
      <origin xyz="-0.0299 0.033 0" rpy="0 -0 0"/>
      <geometry>
        <mesh filename="package://hironx_moveit_config/models/meshes/LHAND_JOINT2_Link_mesh.dae" scale="1 1 1" />
      </geometry>
    </visual>
    <collision>
      <origin xyz="-0.0299 0.033 0" rpy="0 -0 0"/>
      <geometry>
        <mesh filename="package://hironx_moveit_config/models/meshes/LHAND_JOINT2_Link_mesh.dae" scale="1 1 1" />
      </geometry>
    </collision>
    <inertial>
      <mass value="0.01" />
      <origin xyz="0 0 0" rpy="0 -0 0"/>
      <inertia ixx="0" ixy="0" ixz="0" iyy="0" iyz="0" izz="0"/>
    </inertial>
  </link>
  <link name="LHAND_JOINT3_Link">
    <visual>
      <origin xyz="-0.0419 0 0" rpy="0 -0 0"/>
      <geometry>
        <mesh filename="package://hironx_moveit_config/models/meshes/LHAND_JOINT3_Link_mesh.dae" scale="1 1 1" />
      </geometry>
    </visual>
    <collision>
      <origin xyz="-0.0419 0 0" rpy="0 -0 0"/>
      <geometry>
        <mesh filename="package://hironx_moveit_config/models/meshes/LHAND_JOINT3_Link_mesh.dae" scale="1 1 1" />
      </geometry>
    </collision>
    <inertial>
      <mass value="0.01" />
      <origin xyz="0 0 0" rpy="0 -0 0"/>
      <inertia ixx="0" ixy="0" ixz="0" iyy="0" iyz="0" izz="0"/>
    </inertial>
  </link>
  <link name="RARM_JOINT0_Link">
    <visual>
      <origin xyz="0 -0.145 0.370296" rpy="0.261799 -0 0"/>
      <geometry>
        <mesh filename="package://hironx_moveit_config/models/meshes/RARM_JOINT0_Link_mesh.dae" scale="1 1 1" />
      </geometry>
    </visual>
    <collision>
      <origin xyz="0 -0.145 0.370296" rpy="0.261799 -0 0"/>
      <geometry>
        <mesh filename="package://hironx_moveit_config/models/meshes/RARM_JOINT0_Link_mesh.dae" scale="1 1 1" />
      </geometry>
    </collision>
    <inertial>
      <mass value="1.32626" />
      <origin xyz="-0.00226388 0.00521383 0.0156081" rpy="0 -0 0"/>
      <inertia ixx="0" ixy="0" ixz="0" iyy="0" iyz="0" izz="0"/>
    </inertial>
  </link>
  <link name="RARM_JOINT1_Link">
    <visual>
      <origin xyz="0 0 0" rpy="0 -0 0"/>
      <geometry>
        <mesh filename="package://hironx_moveit_config/models/meshes/RARM_JOINT1_Link_mesh.dae" scale="1 1 1" />
      </geometry>
    </visual>
    <collision>
      <origin xyz="0 0 0" rpy="0 -0 0"/>
      <geometry>
        <mesh filename="package://hironx_moveit_config/models/meshes/RARM_JOINT1_Link_mesh.dae" scale="1 1 1" />
      </geometry>
    </collision>
    <inertial>
      <mass value="1.14898" />
      <origin xyz="-5.236e-05 -0.0583134 -0.107061" rpy="0 -0 0"/>
      <inertia ixx="0" ixy="0" ixz="0" iyy="0" iyz="0" izz="0"/>
    </inertial>
  </link>
  <link name="RARM_JOINT2_Link">
    <visual>
      <origin xyz="0 -0.095 -0.25" rpy="0 -0 0"/>
      <geometry>
        <mesh filename="package://hironx_moveit_config/models/meshes/RARM_JOINT2_Link_mesh.dae" scale="1 1 1" />
      </geometry>
    </visual>
    <collision>
      <origin xyz="0 -0.095 -0.25" rpy="0 -0 0"/>
      <geometry>
        <mesh filename="package://hironx_moveit_config/models/meshes/RARM_JOINT2_Link_mesh.dae" scale="1 1 1" />
      </geometry>
    </collision>
    <inertial>
      <mass value="0.577518" />
      <origin xyz="-2.254e-05 -0.00167107 -0.0715116" rpy="0 -0 0"/>
      <inertia ixx="0" ixy="0" ixz="0" iyy="0" iyz="0" izz="0"/>
    </inertial>
  </link>
  <link name="RARM_JOINT3_Link">
    <visual>
      <origin xyz="-0.03 0 0" rpy="0 -0 0"/>
      <geometry>
        <mesh filename="package://hironx_moveit_config/models/meshes/RARM_JOINT3_Link_mesh.dae" scale="1 1 1" />
      </geometry>
    </visual>
    <collision>
      <origin xyz="-0.03 0 0" rpy="0 -0 0"/>
      <geometry>
        <mesh filename="package://hironx_moveit_config/models/meshes/RARM_JOINT3_Link_mesh.dae" scale="1 1 1" />
      </geometry>
    </collision>
    <inertial>
      <mass value="0.457418" />
      <origin xyz="-1.788e-05 0.00395812 -0.202731" rpy="0 -0 0"/>
      <inertia ixx="0" ixy="0" ixz="0" iyy="0" iyz="0" izz="0"/>
    </inertial>
  </link>
  <link name="RARM_JOINT4_Link">
    <visual>
      <origin xyz="0 0 -0.235" rpy="0 -0 0"/>
      <geometry>
        <mesh filename="package://hironx_moveit_config/models/meshes/RARM_JOINT4_Link_mesh.dae" scale="1 1 1" />
      </geometry>
    </visual>
    <collision>
      <origin xyz="0 0 -0.235" rpy="0 -0 0"/>
      <geometry>
        <mesh filename="package://hironx_moveit_config/models/meshes/RARM_JOINT4_Link_mesh.dae" scale="1 1 1" />
      </geometry>
    </collision>
    <inertial>
      <mass value="0.418434" />
      <origin xyz="0.00243131 -0.00379733 -0.0577036" rpy="0 -0 0"/>
      <inertia ixx="0" ixy="0" ixz="0" iyy="0" iyz="0" izz="0"/>
    </inertial>
  </link>
  <link name="RARM_JOINT5_Link">
    <visual>
      <origin xyz="-0.04 0 -0.09" rpy="0 -0 0"/>
      <geometry>
        <mesh filename="package://hironx_moveit_config/models/meshes/RARM_JOINT5_Link_mesh.dae" scale="1 1 1" />
      </geometry>
    </visual>
    <collision>
      <origin xyz="-0.04 0 -0.09" rpy="0 -0 0"/>
      <geometry>
        <mesh filename="package://hironx_moveit_config/models/meshes/RARM_JOINT5_Link_mesh.dae" scale="1 1 1" />
      </geometry>
    </collision>
    <inertial>
      <mass value="1.05156" />
      <origin xyz="-0.048476 3.2e-06 -0.0388988" rpy="0 -0 0"/>
      <inertia ixx="0" ixy="0" ixz="0" iyy="0" iyz="0" izz="0"/>
    </inertial>
  </link>
  <link name="RHAND_JOINT0_Link">
    <visual>
      <origin xyz="-0.0299 -0.033 0" rpy="0 -0 0"/>
      <geometry>
        <mesh filename="package://hironx_moveit_config/models/meshes/RHAND_JOINT0_Link_mesh.dae" scale="1 1 1" />
      </geometry>
    </visual>
    <collision>
      <origin xyz="-0.0299 -0.033 0" rpy="0 -0 0"/>
      <geometry>
        <mesh filename="package://hironx_moveit_config/models/meshes/RHAND_JOINT0_Link_mesh.dae" scale="1 1 1" />
      </geometry>
    </collision>
    <inertial>
      <mass value="0.01" />
      <origin xyz="0 0 0" rpy="0 -0 0"/>
      <inertia ixx="0" ixy="0" ixz="0" iyy="0" iyz="0" izz="0"/>
    </inertial>
  </link>
  <link name="RHAND_JOINT1_Link">
    <visual>
      <origin xyz="-0.0419 0 0" rpy="0 -0 0"/>
      <geometry>
        <mesh filename="package://hironx_moveit_config/models/meshes/RHAND_JOINT1_Link_mesh.dae" scale="1 1 1" />
      </geometry>
    </visual>
    <collision>
      <origin xyz="-0.0419 0 0" rpy="0 -0 0"/>
      <geometry>
        <mesh filename="package://hironx_moveit_config/models/meshes/RHAND_JOINT1_Link_mesh.dae" scale="1 1 1" />
      </geometry>
    </collision>
    <inertial>
      <mass value="0.01" />
      <origin xyz="0 0 0" rpy="0 -0 0"/>
      <inertia ixx="0" ixy="0" ixz="0" iyy="0" iyz="0" izz="0"/>
    </inertial>
  </link>
  <link name="RHAND_JOINT2_Link">
    <visual>
      <origin xyz="-0.0299 0.033 0" rpy="0 -0 0"/>
      <geometry>
        <mesh filename="package://hironx_moveit_config/models/meshes/RHAND_JOINT2_Link_mesh.dae" scale="1 1 1" />
      </geometry>
    </visual>
    <collision>
      <origin xyz="-0.0299 0.033 0" rpy="0 -0 0"/>
      <geometry>
        <mesh filename="package://hironx_moveit_config/models/meshes/RHAND_JOINT2_Link_mesh.dae" scale="1 1 1" />
      </geometry>
    </collision>
    <inertial>
      <mass value="0.01" />
      <origin xyz="0 0 0" rpy="0 -0 0"/>
      <inertia ixx="0" ixy="0" ixz="0" iyy="0" iyz="0" izz="0"/>
    </inertial>
  </link>
  <link name="RHAND_JOINT3_Link">
    <visual>
      <origin xyz="-0.0419 0 0" rpy="0 -0 0"/>
      <geometry>
        <mesh filename="package://hironx_moveit_config/models/meshes/RHAND_JOINT3_Link_mesh.dae" scale="1 1 1" />
      </geometry>
    </visual>
    <collision>
      <origin xyz="-0.0419 0 0" rpy="0 -0 0"/>
      <geometry>
        <mesh filename="package://hironx_moveit_config/models/meshes/RHAND_JOINT3_Link_mesh.dae" scale="1 1 1" />
      </geometry>
    </collision>
    <inertial>
      <mass value="0.01" />
      <origin xyz="0 0 0" rpy="0 -0 0"/>
      <inertia ixx="0" ixy="0" ixz="0" iyy="0" iyz="0" izz="0"/>
    </inertial>
  </link>
  <joint name="CHEST_JOINT0" type="revolute">
    <parent link="WAIST"/>
    <child  link="CHEST_JOINT0_Link"/>
    <origin xyz="0 0 0" rpy="0 -0 0 "/>
    <axis   xyz="0 0 1"/>
    <limit lower="-2.844" upper="2.844" effort="100" velocity="0.5" />
    <dynamics damping="0.2" friction="0" />
  </joint>
  <joint name="HEAD_JOINT0" type="revolute">
    <parent link="CHEST_JOINT0_Link"/>
    <child  link="HEAD_JOINT0_Link"/>
    <origin xyz="0 0 0.5695" rpy="0 -0 0 "/>
    <axis   xyz="0 0 1"/>
    <limit lower="-1.22173" upper="1.22173" effort="100" velocity="0.5" />
    <dynamics damping="0.2" friction="0" />
  </joint>
  <joint name="HEAD_JOINT1" type="revolute">
    <parent link="HEAD_JOINT0_Link"/>
    <child  link="HEAD_JOINT1_Link"/>
    <origin xyz="0 0 0" rpy="0 -0 0 "/>
    <axis   xyz="0 1 0"/>
    <limit lower="-0.349066" upper="1.22173" effort="100" velocity="0.5" />
    <dynamics damping="0.2" friction="0" />
  </joint>
  <joint name="LARM_JOINT0" type="revolute">
    <parent link="CHEST_JOINT0_Link"/>
    <child  link="LARM_JOINT0_Link"/>
    <origin xyz="0 0.145 0.370296" rpy="-0.261799 0 0 "/>
    <axis   xyz="0 0 1"/>
    <limit lower="-1.53589" upper="1.53589" effort="100" velocity="0.5" />
    <dynamics damping="0.2" friction="0" />
  </joint>
  <joint name="LARM_JOINT1" type="revolute">
    <parent link="LARM_JOINT0_Link"/>
    <child  link="LARM_JOINT1_Link"/>
    <origin xyz="0 0 0" rpy="0 -0 0 "/>
    <axis   xyz="0 1 0"/>
    <limit lower="-2.44346" upper="1.0472" effort="100" velocity="0.5" />
    <dynamics damping="0.2" friction="0" />
  </joint>
  <joint name="LARM_JOINT2" type="revolute">
    <parent link="LARM_JOINT1_Link"/>
    <child  link="LARM_JOINT2_Link"/>
    <origin xyz="0 0.095 -0.25" rpy="0 -0 0 "/>
    <axis   xyz="0 1 0"/>
    <limit lower="-2.75762" upper="0" effort="100" velocity="0.5" />
    <dynamics damping="0.2" friction="0" />
  </joint>
  <joint name="LARM_JOINT3" type="revolute">
    <parent link="LARM_JOINT2_Link"/>
    <child  link="LARM_JOINT3_Link"/>
    <origin xyz="-0.03 0 0" rpy="0 -0 0 "/>
    <axis   xyz="0 0 1"/>
    <limit lower="-2.87979" upper="1.8326" effort="100" velocity="0.5" />
    <dynamics damping="0.2" friction="0" />
  </joint>
  <joint name="LARM_JOINT4" type="revolute">
    <parent link="LARM_JOINT3_Link"/>
    <child  link="LARM_JOINT4_Link"/>
    <origin xyz="0 0 -0.235" rpy="0 -0 0 "/>
    <axis   xyz="0 1 0"/>
    <limit lower="-1.74533" upper="1.74533" effort="100" velocity="0.5" />
    <dynamics damping="0.2" friction="0" />
  </joint>
  <joint name="LARM_JOINT5" type="revolute">
    <parent link="LARM_JOINT4_Link"/>
    <child  link="LARM_JOINT5_Link"/>
    <origin xyz="-0.04 0 -0.09" rpy="0 -0 0 "/>
    <axis   xyz="1 0 0"/>
    <limit lower="-2.84489" upper="2.84489" effort="100" velocity="0.5" />
    <dynamics damping="0.2" friction="0" />
  </joint>
  <joint name="LHAND_JOINT0" type="revolute">
    <parent link="LARM_JOINT5_Link"/>
    <child  link="LHAND_JOINT0_Link"/>
    <origin xyz="-0.0299 -0.033 0" rpy="0 -0 0 "/>
    <axis   xyz="0 0 1"/>
    <limit lower="-0.523599" upper="0.523599" effort="100" velocity="0.5" />
    <dynamics damping="0.2" friction="0" />
  </joint>
  <joint name="LHAND_JOINT1" type="revolute">
    <parent link="LHAND_JOINT0_Link"/>
    <child  link="LHAND_JOINT1_Link"/>
    <origin xyz="-0.0419 0 0" rpy="0 -0 0 "/>
    <axis   xyz="0 0 1"/>
    <limit lower="-0.523599" upper="0.523599" effort="100" velocity="0.5" />
    <dynamics damping="0.2" friction="0" />
  </joint>
  <joint name="LHAND_JOINT2" type="revolute">
    <parent link="LARM_JOINT5_Link"/>
    <child  link="LHAND_JOINT2_Link"/>
    <origin xyz="-0.0299 0.033 0" rpy="0 -0 0 "/>
    <axis   xyz="0 0 1"/>
    <limit lower="-0.523599" upper="0.523599" effort="100" velocity="0.5" />
    <dynamics damping="0.2" friction="0" />
  </joint>
  <joint name="LHAND_JOINT3" type="revolute">
    <parent link="LHAND_JOINT2_Link"/>
    <child  link="LHAND_JOINT3_Link"/>
    <origin xyz="-0.0419 0 0" rpy="0 -0 0 "/>
    <axis   xyz="0 0 1"/>
    <limit lower="-0.523599" upper="0.523599" effort="100" velocity="0.5" />
    <dynamics damping="0.2" friction="0" />
  </joint>
  <joint name="RARM_JOINT0" type="revolute">
    <parent link="CHEST_JOINT0_Link"/>
    <child  link="RARM_JOINT0_Link"/>
    <origin xyz="0 -0.145 0.370296" rpy="0.261799 -0 0 "/>
    <axis   xyz="0 0 1"/>
    <limit lower="-1.53589" upper="1.53589" effort="100" velocity="0.5" />
    <dynamics damping="0.2" friction="0" />
  </joint>
  <joint name="RARM_JOINT1" type="revolute">
    <parent link="RARM_JOINT0_Link"/>
    <child  link="RARM_JOINT1_Link"/>
    <origin xyz="0 0 0" rpy="0 -0 0 "/>
    <axis   xyz="0 1 0"/>
    <limit lower="-2.44346" upper="1.0472" effort="100" velocity="0.5" />
    <dynamics damping="0.2" friction="0" />
  </joint>
  <joint name="RARM_JOINT2" type="revolute">
    <parent link="RARM_JOINT1_Link"/>
    <child  link="RARM_JOINT2_Link"/>
    <origin xyz="0 -0.095 -0.25" rpy="0 -0 0 "/>
    <axis   xyz="0 1 0"/>
    <limit lower="-2.75762" upper="0" effort="100" velocity="0.5" />
    <dynamics damping="0.2" friction="0" />
  </joint>
  <joint name="RARM_JOINT3" type="revolute">
    <parent link="RARM_JOINT2_Link"/>
    <child  link="RARM_JOINT3_Link"/>
    <origin xyz="-0.03 0 0" rpy="0 -0 0 "/>
    <axis   xyz="0 0 1"/>
    <limit lower="-2.87979" upper="1.8326" effort="100" velocity="0.5" />
    <dynamics damping="0.2" friction="0" />
  </joint>
  <joint name="RARM_JOINT4" type="revolute">
    <parent link="RARM_JOINT3_Link"/>
    <child  link="RARM_JOINT4_Link"/>
    <origin xyz="0 0 -0.235" rpy="0 -0 0 "/>
    <axis   xyz="0 1 0"/>
    <limit lower="-1.74533" upper="1.74533" effort="100" velocity="0.5" />
    <dynamics damping="0.2" friction="0" />
  </joint>
  <joint name="RARM_JOINT5" type="revolute">
    <parent link="RARM_JOINT4_Link"/>
    <child  link="RARM_JOINT5_Link"/>
    <origin xyz="-0.04 0 -0.09" rpy="0 -0 0 "/>
    <axis   xyz="1 0 0"/>
    <limit lower="-2.84489" upper="2.84489" effort="100" velocity="0.5" />
    <dynamics damping="0.2" friction="0" />
  </joint>
  <joint name="RHAND_JOINT0" type="revolute">
    <parent link="RARM_JOINT5_Link"/>
    <child  link="RHAND_JOINT0_Link"/>
    <origin xyz="-0.0299 -0.033 0" rpy="0 -0 0 "/>
    <axis   xyz="0 0 1"/>
    <limit lower="-0.523599" upper="0.523599" effort="100" velocity="0.5" />
    <dynamics damping="0.2" friction="0" />
  </joint>
  <joint name="RHAND_JOINT1" type="revolute">
    <parent link="RHAND_JOINT0_Link"/>
    <child  link="RHAND_JOINT1_Link"/>
    <origin xyz="-0.0419 0 0" rpy="0 -0 0 "/>
    <axis   xyz="0 0 1"/>
    <limit lower="-0.523599" upper="0.523599" effort="100" velocity="0.5" />
    <dynamics damping="0.2" friction="0" />
  </joint>
  <joint name="RHAND_JOINT2" type="revolute">
    <parent link="RARM_JOINT5_Link"/>
    <child  link="RHAND_JOINT2_Link"/>
    <origin xyz="-0.0299 0.033 0" rpy="0 -0 0 "/>
    <axis   xyz="0 0 1"/>
    <limit lower="-0.523599" upper="0.523599" effort="100" velocity="0.5" />
    <dynamics damping="0.2" friction="0" />
  </joint>
  <joint name="RHAND_JOINT3" type="revolute">
    <parent link="RHAND_JOINT2_Link"/>
    <child  link="RHAND_JOINT3_Link"/>
    <origin xyz="-0.0419 0 0" rpy="0 -0 0 "/>
    <axis   xyz="0 0 1"/>
    <limit lower="-0.523599" upper="0.523599" effort="100" velocity="0.5" />
    <dynamics damping="0.2" friction="0" />
  </joint>
</robot>
